<mujoco model="twoDOFleg">
  <!-- defining some defaults for readability -->
  <default>
    <default class="joint">
      <geom type="cylinder" size=".006" fromto="0 0 0 0 0 .05" rgba=".9 .6 1 1"/>
    </default>
  </default>

  <worldbody>
    <light pos="-0.5 -1 1.5"/>
    <light pos="0.5 -1 1.5"/>
    <geom type="plane" size="1 1 .01" pos="0 0 0"/>
    <camera name="for_video" pos="0.1 -1.4 0.02" xyaxes="1 0 0 0 1 3"/>
    <camera name="overhead" pos="0 0 3" xyaxes="1 0 0 0 1 0"/>
    <body name="torso" pos="0 0 0">
      <geom name="torso_shape" type="box" size="0.1 0.1 0.25" fromto="0 0 0 0 0 0.5"/>
      <body name="femur" pos="0 0 0.5">
        <geom name="femur_shape" type="cylinder" rgba="1 0 0 1" size=".01" fromto="0.15 0 0 0.65 0 0"/>
        <joint name="hip" type="hinge" class="joint" pos="0 0 0" axis="0 1 0" damping="5"/>
        <body name="tibia" pos="0.65 0 0">
          <geom name="tibia_shape" type="cylinder" rgba="0 0 1 1" size=".01" fromto="0.1 0 0 0.6 0 0"/>
          <joint name="knee" type="hinge" class="joint" pos="0 0 0" axis="0 1 0" damping="2"/>
          <site name="end_eff" pos="0.6 0 0" size="0.02"/>
        </body>
      </body>
    </body>
  </worldbody>

  <actuator>
    <position name="servo 1" joint="hip" kp="100"/>
    <position name="servo 2" joint="knee" kp="100"/>
  </actuator>

  <sensor>
    <framepos objtype="site" objname="end_eff"/>
    <framelinvel objtype="site" objname="end_eff"/>
    <touch site="end_eff"/>
  </sensor>
</mujoco>
